Traceback (most recent call last):
  File "/usr/local/lib/python3.12/site-packages/mysql/connector/connection_cext.py", line 323, in _open_connection
    self._cmysql.connect(**cnx_kwargs)
_mysql_connector.MySQLInterfaceError: Can't connect to MySQL server on '127.0.0.1:3306' (111)

The above exception was the direct cause of the following exception:

Traceback (most recent call last):
  File "/app/webapp.py", line 7, in <module>
    cnx = mysql.connector.connect(
          ^^^^^^^^^^^^^^^^^^^^^^^^
  File "/usr/local/lib/python3.12/site-packages/mysql/connector/pooling.py", line 322, in connect
    return CMySQLConnection(*args, **kwargs)
           ^^^^^^^^^^^^^^^^^^^^^^^^^^^^^^^^^
  File "/usr/local/lib/python3.12/site-packages/mysql/connector/connection_cext.py", line 140, in __init__
    self.connect(**kwargs)
  File "/usr/local/lib/python3.12/site-packages/mysql/connector/abstracts.py", line 1363, in connect
    self._open_connection()
  File "/usr/local/lib/python3.12/site-packages/mysql/connector/connection_cext.py", line 328, in _open_connection
    raise get_mysql_exception(
mysql.connector.errors.DatabaseError: 2003 (HY000): Can't connect to MySQL server on '127.0.0.1:3306' (111)
Traceback (most recent call last):
  File "/usr/local/lib/python3.12/site-packages/mysql/connector/connection_cext.py", line 323, in _open_connection
    self._cmysql.connect(**cnx_kwargs)
_mysql_connector.MySQLInterfaceError: Can't connect to MySQL server on '127.0.0.1:3306' (111)

The above exception was the direct cause of the following exception:

Traceback (most recent call last):
  File "/app/webapp.py", line 7, in <module>
    cnx = mysql.connector.connect(
          ^^^^^^^^^^^^^^^^^^^^^^^^
  File "/usr/local/lib/python3.12/site-packages/mysql/connector/pooling.py", line 322, in connect
    return CMySQLConnection(*args, **kwargs)
           ^^^^^^^^^^^^^^^^^^^^^^^^^^^^^^^^^
  File "/usr/local/lib/python3.12/site-packages/mysql/connector/connection_cext.py", line 140, in __init__
    self.connect(**kwargs)
  File "/usr/local/lib/python3.12/site-packages/mysql/connector/abstracts.py", line 1363, in connect
    self._open_connection()
  File "/usr/local/lib/python3.12/site-packages/mysql/connector/connection_cext.py", line 328, in _open_connection
    raise get_mysql_exception(
mysql.connector.errors.DatabaseError: 2003 (HY000): Can't connect to MySQL server on '127.0.0.1:3306' (111)
Traceback (most recent call last):
  File "/usr/local/lib/python3.12/site-packages/mysql/connector/connection_cext.py", line 323, in _open_connection
    self._cmysql.connect(**cnx_kwargs)
_mysql_connector.MySQLInterfaceError: Can't connect to MySQL server on '127.0.0.1:3306' (111)

The above exception was the direct cause of the following exception:

Traceback (most recent call last):
  File "/app/webapp.py", line 7, in <module>
    cnx = mysql.connector.connect(
          ^^^^^^^^^^^^^^^^^^^^^^^^
  File "/usr/local/lib/python3.12/site-packages/mysql/connector/pooling.py", line 322, in connect
    return CMySQLConnection(*args, **kwargs)
           ^^^^^^^^^^^^^^^^^^^^^^^^^^^^^^^^^
  File "/usr/local/lib/python3.12/site-packages/mysql/connector/connection_cext.py", line 140, in __init__
    self.connect(**kwargs)
  File "/usr/local/lib/python3.12/site-packages/mysql/connector/abstracts.py", line 1363, in connect
    self._open_connection()
  File "/usr/local/lib/python3.12/site-packages/mysql/connector/connection_cext.py", line 328, in _open_connection
    raise get_mysql_exception(
mysql.connector.errors.DatabaseError: 2003 (HY000): Can't connect to MySQL server on '127.0.0.1:3306' (111)
Traceback (most recent call last):
  File "/usr/local/lib/python3.12/site-packages/mysql/connector/connection_cext.py", line 323, in _open_connection
    self._cmysql.connect(**cnx_kwargs)
_mysql_connector.MySQLInterfaceError: Can't connect to MySQL server on '127.0.0.1:3306' (111)

The above exception was the direct cause of the following exception:

Traceback (most recent call last):
  File "/app/webapp.py", line 7, in <module>
    cnx = mysql.connector.connect(
          ^^^^^^^^^^^^^^^^^^^^^^^^
  File "/usr/local/lib/python3.12/site-packages/mysql/connector/pooling.py", line 322, in connect
    return CMySQLConnection(*args, **kwargs)
           ^^^^^^^^^^^^^^^^^^^^^^^^^^^^^^^^^
  File "/usr/local/lib/python3.12/site-packages/mysql/connector/connection_cext.py", line 140, in __init__
    self.connect(**kwargs)
  File "/usr/local/lib/python3.12/site-packages/mysql/connector/abstracts.py", line 1363, in connect
    self._open_connection()
  File "/usr/local/lib/python3.12/site-packages/mysql/connector/connection_cext.py", line 328, in _open_connection
    raise get_mysql_exception(
mysql.connector.errors.DatabaseError: 2003 (HY000): Can't connect to MySQL server on '127.0.0.1:3306' (111)
